Workbook

Sheet snippets
A1: filename | B1: right_answer | C1: possible_wrong_answers | D1: number | E1: variant | F1: version | G1: Langhout AoC_category | H1: AoC_category
A2: 10-clean-v0.png | B2: 1 | C2: 0;2 | D2: 10 | E2: clean | F2: v0 | G2: pre increment decrement | H2: prepostindecrement
A3: 10-clean-v1.png | B3: -1 | C3: 0;5 | D3: 10 | E3: clean | F3: v1 | G3: pre increment decrement | H3: prepostindecrement
A4: 10-clean-v2.png | B4: 7 | C4: 6;4 | D4: 10 | E4: clean | F4: v2 | G4: pre increment decrement | H4: prepostindecrement
A5: 10-obf-v0.png | B5: 1 | C5: 0;2 | D5: 10 | E5: obf | F5: v0 | G5: pre increment decrement | H5: prepostindecrement
A6: 10-obf-v1.png | B6: -1 | C6: 0;5 | D6: 10 | E6: obf | F6: v1 | G6: pre increment decrement | H6: prepostindecrement
A7: 10-obf-v2.png | B7: 7 | C7: 6;4 | D7: 10 | E7: obf | F7: v2 | G7: pre increment decrement | H7: prepostindecrement
A8: 11-clean-v0.png | B8: true | C8: false | D8: 11 | E8: clean | F8: v0 | G8: pre increment decrement | H8: prepostindecrement
A9: 11-clean-v1.png | B9: false | C9: true | D9: 11 | E9: clean | F9: v1 | G9: pre increment decrement | H9: prepostindecrement
A10: 11-clean-v2.png | B10: false | C10: true | D10: 11 | E10: clean | F10: v2 | G10: pre increment decrement | H10: prepostindecrement
A11: 11-obf-v0.png | B11: true | C11: false | D11: 11 | E11: obf | F11: v0 | G11: pre increment decrement | H11: prepostindecrement
A12: 11-obf-v1.png | B12: false | C12: true | D12: 11 | E12: obf | F12: v1 | G12: pre increment decrement | H12: prepostindecrement
A13: 11-obf-v2.png | B13: false | C13: true | D13: 11 | E13: obf | F13: v2 | G13: pre increment decrement | H13: prepostindecrement
A14: 12-clean-v0.png | B14: 7 | C14: 6;5 | D14: 12 | E14: clean | F14: v0 | G14: pre increment decrement | H14: prepostindecrement
A15: 12-clean-v1.png | B15: 0 | C15: 1;-1 | D15: 12 | E15: clean | F15: v1 | G15: pre increment decrement | H15: prepostindecrement
A16: 12-clean-v2.png | B16: 4 | C16: 3;2 | D16: 12 | E16: clean | F16: v2 | G16: pre increment decrement | H16: prepostindecrement
A17: 12-obf-v0.png | B17: 7 | C17: 6;5 | D17: 12 | E17: obf | F17: v0 | G17: pre increment decrement | H17: prepostindecrement
A18: 12-obf-v1.png | B18: 0 | C18: 1;-1 | D18: 12 | E18: obf | F18: v1 | G18: pre increment decrement | H18: prepostindecrement
A19: 12-obf-v2.png | B19: 4 | C19: 3;2 | D19: 12 | E19: obf | F19: v2 | G19: pre increment decrement | H19: prepostindecrement
A20: 13-clean-v0.png | B20: 5 | C20: 6;3 | D20: 13 | E20: clean | F20: v0 | G20: constant variables | H20: confusingvariables
A21: 13-clean-v1.png | B21: 11 | C21: 4;7 | D21: 13 | E21: clean | F21: v1 | G21: constant variables | H21: confusingvariables
A22: 13-clean-v2.png | B22: 5 | C22: 6;8 | D22: 13 | E22: clean | F22: v2 | G22: constant variables | H22: confusingvariables
A23: 13-obf-v0.png | B23: 5 | C23: 6;3 | D23: 13 | E23: obf | F23: v0 | G23: constant variables | H23: confusingvariables
A24: 13-obf-v1.png | B24: 11 | C24: 4;7 | D24: 13 | E24: obf | F24: v1 | G24: constant variables | H24: confusingvariables
A25: 13-obf-v2.png | B25: 5 | C25: 6;8 | D25: 13 | E25: obf | F25: v2 | G25: constant variables | H25: confusingvariables
... A31: 14-obf-v2.png | B31: 27 | C31: 30;9 | D31: 14 | E31: obf | F31: v2 | G31: constant variables | H31: confusingvariables
A32: 15-clean-v0.png | B32: 9.0 | C32: 8.0;4.5 | D32: 15 | E32: clean | F32: v0 | G32: constant variables | H32: confusingvariables
A33: 15-clean-v1.png | B33: 13.0 | C33: 12.0;14.0 | D33: 15 | E33: clean | F33: v1 | G33: constant variables | H33: confusingvariables
A34: 15-clean-v2.png | B34: 62.0 | C34: 312.0;63.0 | D34: 15 | E34: clean | F34: v2 | G34: constant variables | H34: confusingvariables
A35: 15-obf-v0.png | B35: 9.0 | C35: 8.0;4.5 | D35: 15 | E35: obf | F35: v0 | G35: constant variables | H35: confusingvariables
A36: 15-obf-v1.png | B36: 13.0 | C36: 12.0;14.0 | D36: 15 | E36: obf | F36: v1 | G36: constant variables | H36: confusingvariables
A37: 15-obf-v2.png | B37: 62.0 | C37: 312.0;63.0 | D37: 15 | E37: obf | F37: v2 | G37: constant variables | H37: confusingvariables
A38: 16-clean-v0.png | B38: 7 | C38: 5;3 | D38: 16 | E38: clean | F38: v0 | G38: remove indentation atom | H38: scopeindentation
A39: 16-clean-v1.png | B39: 5 | C39: 4;6 | D39: 16 | E39: clean | F39: v1 | G39: remove indentation atom | H39: scopeindentation
A40: 16-clean-v2.png | B40: 6 | C40: 4;13 | D40: 16 | E40: clean | F40: v2 | G40: remove indentation atom | H40: scopeindentation
A41: 16-obf-v0.png | B41: 7 | C41: 5;3 | D41: 16 | E41: obf | F41: v0 | G41: remove indentation atom | H41: scopeindentation
A42: 16-obf-v1.png | B42: 5 | C42: 4;6 | D42: 16 | E42: obf | F42: v1 | G42: remove indentation atom | H42: scopeindentation
A43: 16-obf-v2.png | B43: 6 | C43: 4;13 | D43: 16 | E43: obf | F43: v2 | G43: remove indentation atom | H43: scopeindentation
A44: 17-clean-v0.png | B44: 6 | C44: 10;5 | D44: 17 | E44: clean | F44: v0 | G44: remove indentation atom | H44: scopeindentation
A45: 17-clean-v1.png | B45: 1 | C45: 3;4 | D45: 17 | E45: clean | F45: v1 | G45: remove indentation atom | H45: scopeindentation
...

Sheet Result_check
A1: snippet name | B1: result | C1: snippets result from other sheet
A2: -clean-v0 | B2: true | C2: =_xlfn.XLOOKUP(A2&".png",Tabelle1[filename],Tabelle1[right_answer],"",0,1) -> true | D2: =B2=C2 -> TRUE
A3: -obf-v0 | B3: true | C3: =_xlfn.XLOOKUP(A3&".png",Tabelle1[filename],Tabelle1[right_answer],"",0,1) -> true | D3: =B3=C3 -> TRUE
A4: 10-clean-v0 | B4: 1 | C4: =_xlfn.XLOOKUP(A4&".png",Tabelle1[filename],Tabelle1[right_answer],"",0,1) -> 1 | D4: =B4=C4 -> TRUE
A5: 10-obf-v0 | B5: 1 | C5: =_xlfn.XLOOKUP(A5&".png",Tabelle1[filename],Tabelle1[right_answer],"",0,1) -> 1 | D5: =B5=C5 -> TRUE
A6: 11-clean-v0 | B6: true | C6: =_xlfn.XLOOKUP(A6&".png",Tabelle1[filename],Tabelle1[right_answer],"",0,1) -> true | D6: =B6=C6 -> TRUE
A7: 11-obf-v0 | B7: true | C7: =_xlfn.XLOOKUP(A7&".png",Tabelle1[filename],Tabelle1[right_answer],"",0,1) -> true | D7: =B7=C7 -> TRUE
A8: 12-clean-v0 | B8: 7 | C8: =_xlfn.XLOOKUP(A8&".png",Tabelle1[filename],Tabelle1[right_answer],"",0,1) -> 7 | D8: =B8=C8 -> TRUE
A9: 12-obf-v0 | B9: 7 | C9: =_xlfn.XLOOKUP(A9&".png",Tabelle1[filename],Tabelle1[right_answer],"",0,1) -> 7 | D9: =B9=C9 -> TRUE
A10: 13-clean-v0 | B10: 5 | C10: =_xlfn.XLOOKUP(A10&".png",Tabelle1[filename],Tabelle1[right_answer],"",0,1) -> 5 | D10: =B10=C10 -> TRUE
A11: 13-obf-v0 | B11: 5 | C11: =_xlfn.XLOOKUP(A11&".png",Tabelle1[filename],Tabelle1[right_answer],"",0,1) -> 5 | D11: =B11=C11 -> TRUE
A12: 14-clean-v0 | B12: 4 | C12: =_xlfn.XLOOKUP(A12&".png",Tabelle1[filename],Tabelle1[right_answer],"",0,1) -> 4 | D12: =B12=C12 -> TRUE
A13: 14-obf-v0 | B13: 4 | C13: =_xlfn.XLOOKUP(A13&".png",Tabelle1[filename],Tabelle1[right_answer],"",0,1) -> 4 | D13: =B13=C13 -> TRUE
A14: 15-clean-v0 | B14: 9.0 | C14: =_xlfn.XLOOKUP(A14&".png",Tabelle1[filename],Tabelle1[right_answer],"",0,1) -> 9.0 | D14: =B14=C14 -> TRUE
A15: 15-obf-v0 | B15: 9.0 | C15: =_xlfn.XLOOKUP(A15&".png",Tabelle1[filename],Tabelle1[right_answer],"",0,1) -> 9.0 | D15: =B15=C15 -> TRUE
A16: 16-clean-v0 | B16: 7 | C16: =_xlfn.XLOOKUP(A16&".png",Tabelle1[filename],Tabelle1[right_answer],"",0,1) -> 7 | D16: =B16=C16 -> TRUE
A17: 16-obf-v0 | B17: 7 | C17: =_xlfn.XLOOKUP(A17&".png",Tabelle1[filename],Tabelle1[right_answer],"",0,1) -> 7 | D17: =B17=C17 -> TRUE
A18: 17-clean-v0 | B18: 6 | C18: =_xlfn.XLOOKUP(A18&".png",Tabelle1[filename],Tabelle1[right_answer],"",0,1) -> 6 | D18: =B18=C18 -> TRUE
A19: 17-obf-v0 | B19: 6 | C19: =_xlfn.XLOOKUP(A19&".png",Tabelle1[filename],Tabelle1[right_answer],"",0,1) -> 6 | D19: =B19=C19 -> TRUE
A20: 18-clean-v0 | B20: 2 | C20: =_xlfn.XLOOKUP(A20&".png",Tabelle1[filename],Tabelle1[right_answer],"",0,1) -> 2 | D20: =B20=C20 -> TRUE
A21: 18-obf-v0 | B21: 2 | C21: =_xlfn.XLOOKUP(A21&".png",Tabelle1[filename],Tabelle1[right_answer],"",0,1) -> 2 | D21: =B21=C21 -> TRUE
A22: 30-clean-v0 | B22: true | C22: =_xlfn.XLOOKUP(A22&".png",Tabelle1[filename],Tabelle1[right_answer],"",0,1) -> true | D22: =B22=C22 -> TRUE
A23: 30-obf-v0 | B23: true | C23: =_xlfn.XLOOKUP(A23&".png",Tabelle1[filename],Tabelle1[right_answer],"",0,1) -> true | D23: =B23=C23 -> TRUE
A24: 4-clean-v0 | B24: 0 | C24: =_xlfn.XLOOKUP(A24&".png",Tabelle1[filename],Tabelle1[right_answer],"",0,1) -> 0 | D24: =B24=C24 -> TRUE
A25: 4-obf-v0 | B25: 0 | C25: =_xlfn.XLOOKUP(A25&".png",Tabelle1[filename],Tabelle1[right_answer],"",0,1) -> 0 | D25: =B25=C25 -> TRUE
A26: 49-clean-v0 | B26: 2 | C26: =_xlfn.XLOOKUP(A26&".png",Tabelle1[filename],Tabelle1[right_answer],"",0,1) -> 2 | D26: =B26=C26 -> TRUE
A27: 49-obf-v0 | B27: 2 | C27: =_xlfn.XLOOKUP(A27&".png",Tabelle1[filename],Tabelle1[right_answer],"",0,1) -> 2 | D27: =B27=C27 -> TRUE
A28: 5-clean-v0 | B28: true | C28: =_xlfn.XLOOKUP(A28&".png",Tabelle1[filename],Tabelle1[right_answer],"",0,1) -> true | D28: =B28=C28 -> TRUE
A29: 5-obf-v0 | B29: true | C29: =_xlfn.XLOOKUP(A29&".png",Tabelle1[filename],Tabelle1[right_answer],"",0,1) -> true | D29: =B29=C29 -> TRUE
A30: 54-clean-v0 | B30: 0 | C30: =_xlfn.XLOOKUP(A30&".png",Tabelle1[filename],Tabelle1[right_answer],"",0,1) -> 0 | D30: =B30=C30 -> TRUE
A31: 54-obf-v0 | B31: 0 | C31: =_xlfn.XLOOKUP(A31&".png",Tabelle1[filename],Tabelle1[right_answer],"",0,1) -> 0 | D31: =B31=C31 -> TRUE
A32: 57-clean-v0 | B32: 8 | C32: =_xlfn.XLOOKUP(A32&".png",Tabelle1[filename],Tabelle1[right_answer],"",0,1) -> 8 | D32: =B32=C32 -> TRUE
A33: 57-obf-v0 | B33: 8 | C33: =_xlfn.XLOOKUP(A33&".png",Tabelle1[filename],Tabelle1[right_answer],"",0,1) -> 8 | D33: =B33=C33 -> TRUE
A34: 6-clean-v0 | B34: true | C34: =_xlfn.XLOOKUP(A34&".png",Tabelle1[filename],Tabelle1[right_answer],"",0,1) -> true | D34: =B34=C34 -> TRUE
A35: 6-obf-v0 | B35: true | C35: =_xlfn.XLOOKUP(A35&".png",Tabelle1[filename],Tabelle1[right_answer],"",0,1) -> true | D35: =B35=C35 -> TRUE
A36: 60-clean-v0 | B36: 32 | C36: =_xlfn.XLOOKUP(A36&".png",Tabelle1[filename],Tabelle1[right_answer],"",0,1) -> 32 | D36: =B36=C36 -> TRUE
A37: 60-obf-v0 | B37: 32 | C37: =_xlfn.XLOOKUP(A37&".png",Tabelle1[filename],Tabelle1[right_answer],"",0,1) -> 32 | D37: =B37=C37 -> TRUE
A38: 61-clean-v0 | B38: 4 | C38: =_xlfn.XLOOKUP(A38&".png",Tabelle1[filename],Tabelle1[right_answer],"",0,1) -> 4 | D38: =B38=C38 -> TRUE
A39: 61-obf-v0 | B39: 4 | C39: =_xlfn.XLOOKUP(A39&".png",Tabelle1[filename],Tabelle1[right_answer],"",0,1) -> 4 | D39: =B39=C39 -> TRUE
A40: 62-clean-v0 | B40: 3 | C40: =_xlfn.XLOOKUP(A40&".png",Tabelle1[filename],Tabelle1[right_answer],"",0,1) -> 3 | D40: =B40=C40 -> TRUE
...

Sheet P003 P004
A1: filename | B1: right_answer | C1: possible_wrong_answers | D1: number | E1: variant | F1: version | G1: Spalte1
A2: 4-clean-v0.png | B2: 0 | C2: -1;-2 | D2: 4 | E2: clean | F2: v0 | G2: 0 | K2: check dass 50% cleck und 50% obf bei random partition sind | L2: =SUM(G2,G4,G6,G8,G10,G12,G14,G16,G18,G20,G22,G24,G26,G28,G30,G32,G34,G36,G38,G40,G42,G44,G46,G48) -> 12
A3: 4-obf-v0.png | B3: 0 | C3: -1;-2 | D3: 4 | E3: obf | F3: v0 | G3: 1
A4: 5-clean-v0.png | B4: true | C4: false | D4: 5 | E4: clean | F4: v0 | G4: 0
A5: 5-obf-v0.png | B5: true | C5: false | D5: 5 | E5: obf | F5: v0 | G5: 1
A6: 6-clean-v0.png | B6: true | C6: false | D6: 6 | E6: clean | F6: v0 | G6: 1 | I6: filename | J6: right_answer | K6: possible_wrong_answers | L6: number | M6: variant | N6: version | O6: Spalte1
A7: 6-obf-v0.png | B7: true | C7: false | D7: 6 | E7: obf | F7: v0 | G7: 0 | I7: 63-clean-v0.png | J7: 9 | K7: 7;5 | L7: 63 | M7: clean | N7: v0 | O7: 1 | P7: {=_xlfn.XLOOKUP(Tabelle3[[#This Row],[filename]],Answer_Button_Distribution!$A$2:$A$153,Answer_Button_Distribution!$E$2:$G$153,"",0,1)} -> 5 | Q7: 7 | R7: 9
A8: 7-clean-v0.png | B8: 5 | C8: 6;7 | D8: 7 | E8: clean | F8: v0 | G8: 0 | I8: 62-obf-v0.png | J8: 3 | K8: 6;1 | L8: 62 | M8: obf | N8: v0 | O8: 1 | P8: {=_xlfn.XLOOKUP(Tabelle3[[#This Row],[filename]],Answer_Button_Distribution!$A$2:$A$153,Answer_Button_Distribution!$E$2:$G$153,"",0,1)} -> 1 | Q8: 3 | R8: 6
A9: 7-obf-v0.png | B9: 5 | C9: 6;7 | D9: 7 | E9: obf | F9: v0 | G9: 1 | I9: 17-clean-v0.png | J9: 6 | K9: 10;5 | L9: 17 | M9: clean | N9: v0 | O9: 1 | P9: {=_xlfn.XLOOKUP(Tabelle3[[#This Row],[filename]],Answer_Button_Distribution!$A$2:$A$153,Answer_Button_Distribution!$E$2:$G$153,"",0,1)} -> 5 | Q9: 6 | R9: 10
A10: 8-clean-v0.png | B10: true | C10: false | D10: 8 | E10: clean | F10: v0 | G10: 1 | I10: -clean-v0.png | J10: true | K10: false | M10: clean | N10: v0 | O10: 1 | P10: {=_xlfn.XLOOKUP(Tabelle3[[#This Row],[filename]],Answer_Button_Distribution!$A$2:$A$153,Answer_Button_Distribution!$E$2:$G$153,"",0,1)} -> false | Q10: true | R10: EMPTY
A11: 8-obf-v0.png | B11: true | C11: false | D11: 8 | E11: obf | F11: v0 | G11: 0 | I11: 7-obf-v0.png | J11: 5 | K11: 6;7 | L11: 7 | M11: obf | N11: v0 | O11: 1 | P11: {=_xlfn.XLOOKUP(Tabelle3[[#This Row],[filename]],Answer_Button_Distribution!$A$2:$A$153,Answer_Button_Distribution!$E$2:$G$153,"",0,1)} -> 5 | Q11: 6 | R11: 7
A12: 9-clean-v0.png | B12: false | C12: true | D12: 9 | E12: clean | F12: v0 | G12: 1 | I12: 12-clean-v0.png | J12: 7 | K12: 6;5 | L12: 12 | M12: clean | N12: v0 | O12: 1 | P12: {=_xlfn.XLOOKUP(Tabelle3[[#This Row],[filename]],Answer_Button_Distribution!$A$2:$A$153,Answer_Button_Distribution!$E$2:$G$153,"",0,1)} -> 5 | Q12: 6 | R12: 7
A13: 9-obf-v0.png | B13: false | C13: true | D13: 9 | E13: obf | F13: v0 | G13: 0 | I13: 5-obf-v0.png | J13: true | K13: false | L13: 5 | M13: obf | N13: v0 | O13: 1 | P13: {=_xlfn.XLOOKUP(Tabelle3[[#This Row],[filename]],Answer_Button_Distribution!$A$2:$A$153,Answer_Button_Distribution!$E$2:$G$153,"",0,1)} -> false | Q13: true | R13: EMPTY
A14: 10-clean-v0.png | B14: 1 | C14: 0;2 | D14: 10 | E14: clean | F14: v0 | G14: 0 | I14: 10-obf-v0.png | J14: 1 | K14: 0;2 | L14: 10 | M14: obf | N14: v0 | O14: 1 | P14: {=_xlfn.XLOOKUP(Tabelle3[[#This Row],[filename]],Answer_Button_Distribution!$A$2:$A$153,Answer_Button_Distribution!$E$2:$G$153,"",0,1)} -> 0 | Q14: 1 | R14: 2
A15: 10-obf-v0.png | B15: 1 | C15: 0;2 | D15: 10 | E15: obf | F15: v0 | G15: 1 | I15: 60-clean-v0.png | J15: 32 | K15: 256;288 | L15: 60 | M15: clean | N15: v0 | O15: 1 | P15: {=_xlfn.XLOOKUP(Tabelle3[[#This Row],[filename]],Answer_Button_Distribution!$A$2:$A$153,Answer_Button_Distribution!$E$2:$G$153,"",0,1)} -> 32 | Q15: 256 | R15: 288
A16: 11-clean-v0.png | B16: true | C16: false | D16: 11 | E16: clean | F16: v0 | G16: 0 | I16: 61-obf-v0.png | J16: 4 | K16: 2;0 | L16: 61 | M16: obf | N16: v0 | O16: 1 | P16: {=_xlfn.XLOOKUP(Tabelle3[[#This Row],[filename]],Answer_Button_Distribution!$A$2:$A$153,Answer_Button_Distribution!$E$2:$G$153,"",0,1)} -> 0 | Q16: 2 | R16: 4
A17: 11-obf-v0.png | B17: true | C17: false | D17: 11 | E17: obf | F17: v0 | G17: 1 | I17: 14-obf-v0.png | J17: 4 | K17: 1;2 | L17: 14 | M17: obf | N17: v0 | O17: 1 | P17: {=_xlfn.XLOOKUP(Tabelle3[[#This Row],[filename]],Answer_Button_Distribution!$A$2:$A$153,Answer_Button_Distribution!$E$2:$G$153,"",0,1)} -> 1 | Q17: 2 | R17: 4
A18: 12-clean-v0.png | B18: 7 | C18: 6;5 | D18: 12 | E18: clean | F18: v0 | G18: 1 | I18: 16-clean-v0.png | J18: 7 | K18: 5;3 | L18: 16 | M18: clean | N18: v0 | O18: 1 | P18: {=_xlfn.XLOOKUP(Tabelle3[[#This Row],[filename]],Answer_Button_Distribution!$A$2:$A$153,Answer_Button_Distribution!$E$2:$G$153,"",0,1)} -> 3 | Q18: 5 | R18: 7
A19: 12-obf-v0.png | B19: 7 | C19: 6;5 | D19: 12 | E19: obf | F19: v0 | G19: 0 | I19: 49-obf-v0.png | J19: 2 | K19: 1;3 | L19: 49 | M19: obf | N19: v0 | O19: 1 | P19: {=_xlfn.XLOOKUP(Tabelle3[[#This Row],[filename]],Answer_Button_Distribution!$A$2:$A$153,Answer_Button_Distribution!$E$2:$G$153,"",0,1)} -> 1 | Q19: 2 | R19: 3
A20: 13-clean-v0.png | B20: 5 | C20: 6;3 | D20: 13 | E20: clean | F20: v0 | G20: 0 | I20: 18-obf-v0.png | J20: 2 | K20: 1;3 | L20: 18 | M20: obf | N20: v0 | O20: 1 | P20: {=_xlfn.XLOOKUP(Tabelle3[[#This Row],[filename]],Answer_Button_Distribution!$A$2:$A$153,Answer_Button_Distribution!$E$2:$G$153,"",0,1)} -> 1 | Q20: 2 | R20: 3
A21: 13-obf-v0.png | B21: 5 | C21: 6;3 | D21: 13 | E21: obf | F21: v0 | G21: 1 | I21: 15-clean-v0.png | J21: 9.0 | K21: 8.0;4.5 | L21: 15 | M21: clean | N21: v0 | O21: 1 | P21: {=_xlfn.XLOOKUP(Tabelle3[[#This Row],[filename]],Answer_Button_Distribution!$A$2:$A$153,Answer_Button_Distribution!$E$2:$G$153,"",0,1)} -> 4.5 | Q21: 8.0 | R21: 9.0
A22: 14-clean-v0.png | B22: 4 | C22: 1;2 | D22: 14 | E22: clean | F22: v0 | G22: 0 | I22: 6-clean-v0.png | J22: true | K22: false | L22: 6 | M22: clean | N22: v0 | O22: 1 | P22: {=_xlfn.XLOOKUP(Tabelle3[[#This Row],[filename]],Answer_Button_Distribution!$A$2:$A$153,Answer_Button_Distribution!$E$2:$G$153,"",0,1)} -> false | Q22: true | R22: EMPTY
A23: 14-obf-v0.png | B23: 4 | C23: 1;2 | D23: 14 | E23: obf | F23: v0 | G23: 1 | I23: 54-clean-v0.png | J23: 0 | K23: 15;12 | L23: 54 | M23: clean | N23: v0 | O23: 1 | P23: {=_xlfn.XLOOKUP(Tabelle3[[#This Row],[filename]],Answer_Button_Distribution!$A$2:$A$153,Answer_Button_Distribution!$E$2:$G$153,"",0,1)} -> 0 | Q23: 12 | R23: 15
A24: 15-clean-v0.png | B24: 9.0 | C24: 8.0;4.5 | D24: 15 | E24: clean | F24: v0 | G24: 1 | I24: 4-obf-v0.png | J24: 0 | K24: -1;-2 | L24: 4 | M24: obf | N24: v0 | O24: 1 | P24: {=_xlfn.XLOOKUP(Tabelle3[[#This Row],[filename]],Answer_Button_Distribution!$A$2:$A$153,Answer_Button_Distribution!$E$2:$G$153,"",0,1)} -> -2 | Q24: -1 | R24: 0
A25: 15-obf-v0.png | B25: 9.0 | C25: 8.0;4.5 | D25: 15 | E25: obf | F25: v0 | G25: 0 | I25: 13-obf-v0.png | J25: 5 | K25: 6;3 | L25: 13 | M25: obf | N25: v0 | O25: 1 | P25: {=_xlfn.XLOOKUP(Tabelle3[[#This Row],[filename]],Answer_Button_Distribution!$A$2:$A$153,Answer_Button_Distribution!$E$2:$G$153,"",0,1)} -> 3 | Q25: 5 | R25: 6
A26: 16-clean-v0.png | B26: 7 | C26: 5;3 | D26: 16 | E26: clean | F26: v0 | G26: 1 | I26: 8-clean-v0.png | J26: true | K26: false | L26: 8 | M26: clean | N26: v0 | O26: 1 | P26: {=_xlfn.XLOOKUP(Tabelle3[[#This Row],[filename]],Answer_Button_Distribution!$A$2:$A$153,Answer_Button_Distribution!$E$2:$G$153,"",0,1)} -> false | Q26: true | R26: EMPTY
A27: 16-obf-v0.png | B27: 7 | C27: 5;3 | D27: 16 | E27: obf | F27: v0 | G27: 0 | I27: 11-obf-v0.png | J27: true | K27: false | L27: 11 | M27: obf | N27: v0 | O27: 1 | P27: {=_xlfn.XLOOKUP(Tabelle3[[#This Row],[filename]],Answer_Button_Distribution!$A$2:$A$153,Answer_Button_Distribution!$E$2:$G$153,"",0,1)} -> false | Q27: true | R27: EMPTY
A28: 17-clean-v0.png | B28: 6 | C28: 10;5 | D28: 17 | E28: clean | F28: v0 | G28: 1 | I28: 57-clean-v0.png | J28: 8 | K28: 5;10 | L28: 57 | M28: clean | N28: v0 | O28: 1 | P28: {=_xlfn.XLOOKUP(Tabelle3[[#This Row],[filename]],Answer_Button_Distribution!$A$2:$A$153,Answer_Button_Distribution!$E$2:$G$153,"",0,1)} -> 5 | Q28: 8 | R28: 10
A29: 17-obf-v0.png | B29: 6 | C29: 10;5 | D29: 17 | E29: obf | F29: v0 | G29: 0 | I29: 30-obf-v0.png | J29: true | K29: false | L29: 30 | M29: obf | N29: v0 | O29: 1 | P29: {=_xlfn.XLOOKUP(Tabelle3[[#This Row],[filename]],Answer_Button_Distribution!$A$2:$A$153,Answer_Button_Distribution!$E$2:$G$153,"",0,1)} -> false | Q29: true | R29: EMPTY
A30: 18-clean-v0.png | B30: 2 | C30: 1;3 | D30: 18 | E30: clean | F30: v0 | G30: 0 | I30: 9-clean-v0.png | J30: false | K30: true | L30: 9 | M30: clean | N30: v0 | O30: 1 | P30: {=_xlfn.XLOOKUP(Tabelle3[[#This Row],[filename]],Answer_Button_Distribution!$A$2:$A$153,Answer_Button_Distribution!$E$2:$G$153,"",0,1)} -> false | Q30: true | R30: EMPTY
A31: 18-obf-v0.png | B31: 2 | C31: 1;3 | D31: 18 | E31: obf | F31: v0 | G31: 1 | I31: 5-obf-v1.png | J31: true | K31: false | L31: 5 | M31: obf | N31: v1 | O31: 1 | P31: {=_xlfn.XLOOKUP(Tabelle3[[#This Row],[filename]],Answer_Button_Distribution!$A$2:$A$153,Answer_Button_Distribution!$E$2:$G$153,"",0,1)} -> false | Q31: true | R31: EMPTY
A32: 30-clean-v0.png | B32: true | C32: false | D32: 30 | E32: clean | F32: v0 | G32: 0 | I32: 16-clean-v1.png | J32: 5 | K32: 4;6 | L32: 16 | M32: clean | N32: v1 | O32: 1 | P32: {=_xlfn.XLOOKUP(Tabelle3[[#This Row],[filename]],Answer_Button_Distribution!$A$2:$A$153,Answer_Button_Distribution!$E$2:$G$153,"",0,1)} -> 4 | Q32: 5 | R32: 6
A33: 30-obf-v0.png | B33: true | C33: false | D33: 30 | E33: obf | F33: v0 | G33: 1 | I33: 61-obf-v1.png | J33: 256 | K33: 128;42 | L33: 61 | M33: obf | N33: v1 | O33: 1 | P33: {=_xlfn.XLOOKUP(Tabelle3[[#This Row],[filename]],Answer_Button_Distribution!$A$2:$A$153,Answer_Button_Distribution!$E$2:$G$153,"",0,1)} -> 42 | Q33: 128 | R33: 256
A34: 49-clean-v0.png | B34: 2 | C34: 1;3 | D34: 49 | E34: clean | F34: v0 | G34: 0 | I34: 18-obf-v1.png | J34: 2 | K34: 5;7 | L34: 18 | M34: obf | N34: v1 | O34: 1 | P34: {=_xlfn.XLOOKUP(Tabelle3[[#This Row],[filename]],Answer_Button_Distribution!$A$2:$A$153,Answer_Button_Distribution!$E$2:$G$153,"",0,1)} -> 2 | Q34: 5 | R34: 7
A35: 49-obf-v0.png | B35: 2 | C35: 1;3 | D35: 49 | E35: obf | F35: v0 | G35: 1 | I35: -clean-v1.png | J35: false | K35: true | M35: clean | N35: v1 | O35: 1 | P35: {=_xlfn.XLOOKUP(Tabelle3[[#This Row],[filename]],Answer_Button_Distribution!$A$2:$A$153,Answer_Button_Distribution!$E$2:$G$153,"",0,1)} -> false | Q35: true | R35: EMPTY
A36: 54-clean-v0.png | B36: 0 | C36: 15;12 | D36: 54 | E36: clean | F36: v0 | G36: 1 | I36: 57-clean-v1.png | J36: 10 | K36: 13;6 | L36: 57 | M36: clean | N36: v1 | O36: 1 | P36: {=_xlfn.XLOOKUP(Tabelle3[[#This Row],[filename]],Answer_Button_Distribution!$A$2:$A$153,Answer_Button_Distribution!$E$2:$G$153,"",0,1)} -> 6 | Q36: 10 | R36: 13
A37: 54-obf-v0.png | B37: 0 | C37: 15;12 | D37: 54 | E37: obf | F37: v0 | G37: 0 | I37: 62-obf-v1.png | J37: 60 | K37: 30;84 | L37: 62 | M37: obf | N37: v1 | O37: 1 | P37: {=_xlfn.XLOOKUP(Tabelle3[[#This Row],[filename]],Answer_Button_Distribution!$A$2:$A$153,Answer_Button_Distribution!$E$2:$G$153,"",0,1)} -> 30 | Q37: 60 | R37: 84
A38: 57-clean-v0.png | B38: 8 | C38: 5;10 | D38: 57 | E38: clean | F38: v0 | G38: 1 | I38: 15-clean-v1.png | J38: 13.0 | K38: 12.0;14.0 | L38: 15 | M38: clean | N38: v1 | O38: 1 | P38: {=_xlfn.XLOOKUP(Tabelle3[[#This Row],[filename]],Answer_Button_Distribution!$A$2:$A$153,Answer_Button_Distribution!$E$2:$G$153,"",0,1)} -> 12.0 | Q38: 13.0 | R38: 14.0
A39: 57-obf-v0.png | B39: 8 | C39: 5;10 | D39: 57 | E39: obf | F39: v0 | G39: 0 | I39: 54-clean-v1.png | J39: 9 | K39: 15;24 | L39: 54 | M39: clean | N39: v1 | O39: 1 | P39: {=_xlfn.XLOOKUP(Tabelle3[[#This Row],[filename]],Answer_Button_Distribution!$A$2:$A$153,Answer_Button_Distribution!$E$2:$G$153,"",0,1)} -> 9 | Q39: 15 | R39: 24
A40: 60-clean-v0.png | B40: 32 | C40: 256;288 | D40: 60 | E40: clean | F40: v0 | G40: 1 | I40: 11-obf-v1.png | J40: false | K40: true | L40: 11 | M40: obf | N40: v1 | O40: 1 | P40: {=_xlfn.XLOOKUP(Tabelle3[[#This Row],[filename]],Answer_Button_Distribution!$A$2:$A$153,Answer_Button_Distribution!$E$2:$G$153,"",0,1)} -> false | Q40: true | R40: EMPTY
...

Sheet Answer_Button_Distribution
A1: Original | E1: sorted
A2: filename | B2: right_answer | C2: wrong_answer1 | D2: wrong_answer2 | E2: answer1 | F2: answer2 | G2: answer3 | H2: correct_index | I2: typ | K2: Anzahl von filename | L2: Spaltenbeschriftungen
A3: 10-clean-v0.png | B3: 1 | C3: 0 | D3: 2 | E3: {=IF(D3="",_xlfn._xlws.SORT(B3:C3,1,1,TRUE),_xlfn._xlws.SORT(B3:D3,1,1,TRUE))} -> 0 | F3: 1 | G3: 2 | H3: =IF(B3=E3,1,IF(B3=F3,2,3)) -> 2 | I3: number | J3: =LEFT(A3,LEN(A3)-4) -> 10-clean-v0 | K3: Zeilenbeschriftungen | L3: 1 | M3: 2 | N3: 3 | O3: Gesamtergebnis | V3: minImprovementPerRound:[0.05,0.1,0.3,0.5] | W3: quadraticFunctionSupport:[true,false] | X3: learn-logFunction:[true,false] | Y3: learn-accumulatedLogFunction:[true,false] | Z3: learn-asymFunction:[true,false] | AA3: learn-ratioFunction:[true,false] | AB3: learn-mirrowedFunction:[true,false] | AC3: numberOfRounds:[5,10,20,30]
A4: 10-clean-v1.png | B4: -1 | C4: 0 | D4: 5 | E4: {=IF(D4="",_xlfn._xlws.SORT(B4:C4,1,1,TRUE),_xlfn._xlws.SORT(B4:D4,1,1,TRUE))} -> -1 | F4: 0 | G4: 5 | H4: =IF(B4=E4,1,IF(B4=F4,2,3)) -> 1 | I4: number | J4: =LEFT(A4,LEN(A4)-4) -> 10-clean-v1 | K4: bool | L4: 20 | M4: 22 | O4: 42
A5: 10-clean-v2.png | B5: 7 | C5: 6 | D5: 4 | E5: {=IF(D5="",_xlfn._xlws.SORT(B5:C5,1,1,TRUE),_xlfn._xlws.SORT(B5:D5,1,1,TRUE))} -> 4 | F5: 6 | G5: 7 | H5: =IF(B5=E5,1,IF(B5=F5,2,3)) -> 3 | I5: number | J5: =LEFT(A5,LEN(A5)-4) -> 10-clean-v2 | K5: number | L5: 34 | M5: 34 | N5: 34 | O5: 102 | V5: minImprovementPerRound | W5: [0.05 | X5: 0.1 | Y5: 0.3 | Z5: 0.5] | AB5: 4
A6: 10-obf-v0.png | B6: 1 | C6: 0 | D6: 2 | E6: {=IF(D6="",_xlfn._xlws.SORT(B6:C6,1,1,TRUE),_xlfn._xlws.SORT(B6:D6,1,1,TRUE))} -> 0 | F6: 1 | G6: 2 | H6: =IF(B6=E6,1,IF(B6=F6,2,3)) -> 2 | I6: number | J6: =LEFT(A6,LEN(A6)-4) -> 10-obf-v0 | K6: Gesamtergebnis | L6: 54 | M6: 56 | N6: 34 | O6: 144 | V6: quadraticFunctionSupport | W6: [true | X6: false] | AB6: 2
A7: 10-obf-v1.png | B7: -1 | C7: 0 | D7: 5 | E7: {=IF(D7="",_xlfn._xlws.SORT(B7:C7,1,1,TRUE),_xlfn._xlws.SORT(B7:D7,1,1,TRUE))} -> -1 | F7: 0 | G7: 5 | H7: =IF(B7=E7,1,IF(B7=F7,2,3)) -> 1 | I7: number | J7: =LEFT(A7,LEN(A7)-4) -> 10-obf-v1 | V7: learn-logFunction | W7: [true | X7: false] | AB7: 2
A8: 10-obf-v2.png | B8: 7 | C8: 6 | D8: 4 | E8: {=IF(D8="",_xlfn._xlws.SORT(B8:C8,1,1,TRUE),_xlfn._xlws.SORT(B8:D8,1,1,TRUE))} -> 4 | F8: 6 | G8: 7 | H8: =IF(B8=E8,1,IF(B8=F8,2,3)) -> 3 | I8: number | J8: =LEFT(A8,LEN(A8)-4) -> 10-obf-v2 | V8: learn-accumulatedLogFunction | W8: [true | X8: false] | AB8: 2
A9: 11-clean-v0.png | B9: true | C9: false | D9: EMPTY | E9: {=IF(D9="EMPTY",_xlfn._xlws.SORT(B9:C9,1,1,TRUE),_xlfn._xlws.SORT(B9:D9,1,1,TRUE))} -> false | F9: true | G9: EMPTY | H9: =IF(B9=E9,1,IF(B9=F9,2,3)) -> 2 | I9: bool | J9: =LEFT(A9,LEN(A9)-4) -> 11-clean-v0 | L9: =GETPIVOTDATA("filename",$K$2,"correct_index",1,"typ","bool")/GETPIVOTDATA("filename",$K$2,"typ","bool") -> 0.47619048 | M9: =GETPIVOTDATA("filename",$K$2,"correct_index",2,"typ","bool")/GETPIVOTDATA("filename",$K$2,"typ","bool") -> 0.52380952 | V9: learn-asymFunction | W9: [true | X9: false] | AB9: 2
A10: 11-clean-v1.png | B10: false | C10: true | D10: EMPTY | E10: {=IF(D10="EMPTY",_xlfn._xlws.SORT(B10:C10,1,1,TRUE),_xlfn._xlws.SORT(B10:D10,1,1,TRUE))} -> false | F10: true | G10: EMPTY | H10: =IF(B10=E10,1,IF(B10=F10,2,3)) -> 1 | I10: bool | J10: =LEFT(A10,LEN(A10)-4) -> 11-clean-v1 | L10: =GETPIVOTDATA("filename",$K$2,"correct_index",1,"typ","number")/GETPIVOTDATA("filename",$K$2,"typ","number") -> 0.33333333 | M10: =GETPIVOTDATA("filename",$K$2,"correct_index",2,"typ","number")/GETPIVOTDATA("filename",$K$2,"typ","number") -> 0.33333333 | N10: =GETPIVOTDATA("filename",$K$2,"correct_index",3,"typ","number")/GETPIVOTDATA("filename",$K$2,"typ","number") -> 0.33333333 | V10: learn-ratioFunction | W10: [true | X10: false] | AB10: 2
A11: 11-clean-v2.png | B11: false | C11: true | D11: EMPTY | E11: {=IF(D11="EMPTY",_xlfn._xlws.SORT(B11:C11,1,1,TRUE),_xlfn._xlws.SORT(B11:D11,1,1,TRUE))} -> false | F11: true | G11: EMPTY | H11: =IF(B11=E11,1,IF(B11=F11,2,3)) -> 1 | I11: bool | J11: =LEFT(A11,LEN(A11)-4) -> 11-clean-v2 | V11: learn-mirrowedFunction | W11: [true | X11: false] | AB11: 2
A12: 11-obf-v0.png | B12: true | C12: false | D12: EMPTY | E12: {=IF(D12="EMPTY",_xlfn._xlws.SORT(B12:C12,1,1,TRUE),_xlfn._xlws.SORT(B12:D12,1,1,TRUE))} -> false | F12: true | G12: EMPTY | H12: =IF(B12=E12,1,IF(B12=F12,2,3)) -> 2 | I12: bool | J12: =LEFT(A12,LEN(A12)-4) -> 11-obf-v0 | V12: numberOfRounds | W12: [5 | X12: 10 | Y12: 20 | Z12: 30] | AB12: 4
A13: 11-obf-v1.png | B13: false | C13: true | D13: EMPTY | E13: {=IF(D13="EMPTY",_xlfn._xlws.SORT(B13:C13,1,1,TRUE),_xlfn._xlws.SORT(B13:D13,1,1,TRUE))} -> false | F13: true | G13: EMPTY | H13: =IF(B13=E13,1,IF(B13=F13,2,3)) -> 1 | I13: bool | J13: =LEFT(A13,LEN(A13)-4) -> 11-obf-v1 | AB13: 5
A14: 11-obf-v2.png | B14: false | C14: true | D14: EMPTY | E14: {=IF(D14="EMPTY",_xlfn._xlws.SORT(B14:C14,1,1,TRUE),_xlfn._xlws.SORT(B14:D14,1,1,TRUE))} -> false | F14: true | G14: EMPTY | H14: =IF(B14=E14,1,IF(B14=F14,2,3)) -> 1 | I14: bool | J14: =LEFT(A14,LEN(A14)-4) -> 11-obf-v2 | AB14: =PRODUCT(AB5:AB13) -> 5120
A15: 12-clean-v0.png | B15: 7 | C15: 6 | D15: 5 | E15: {=IF(D15="",_xlfn._xlws.SORT(B15:C15,1,1,TRUE),_xlfn._xlws.SORT(B15:D15,1,1,TRUE))} -> 5 | F15: 6 | G15: 7 | H15: =IF(B15=E15,1,IF(B15=F15,2,3)) -> 3 | I15: number | J15: =LEFT(A15,LEN(A15)-4) -> 12-clean-v0
A16: 12-clean-v1.png | B16: 0 | C16: 1 | D16: -1 | E16: {=IF(D16="",_xlfn._xlws.SORT(B16:C16,1,1,TRUE),_xlfn._xlws.SORT(B16:D16,1,1,TRUE))} -> -1 | F16: 0 | G16: 1 | H16: =IF(B16=E16,1,IF(B16=F16,2,3)) -> 2 | I16: number | J16: =LEFT(A16,LEN(A16)-4) -> 12-clean-v1
A17: 12-clean-v2.png | B17: 4 | C17: 3 | D17: 2 | E17: {=IF(D17="",_xlfn._xlws.SORT(B17:C17,1,1,TRUE),_xlfn._xlws.SORT(B17:D17,1,1,TRUE))} -> 2 | F17: 3 | G17: 4 | H17: =IF(B17=E17,1,IF(B17=F17,2,3)) -> 3 | I17: number | J17: =LEFT(A17,LEN(A17)-4) -> 12-clean-v2 | AB17: 4725
A18: 12-obf-v0.png | B18: 7 | C18: 6 | D18: 5 | E18: {=IF(D18="",_xlfn._xlws.SORT(B18:C18,1,1,TRUE),_xlfn._xlws.SORT(B18:D18,1,1,TRUE))} -> 5 | F18: 6 | G18: 7 | H18: =IF(B18=E18,1,IF(B18=F18,2,3)) -> 3 | I18: number | J18: =LEFT(A18,LEN(A18)-4) -> 12-obf-v0 | AB18: =45+15/24 -> 45.625
A19: 12-obf-v1.png | B19: 0 | C19: 1 | D19: -1 | E19: {=IF(D19="",_xlfn._xlws.SORT(B19:C19,1,1,TRUE),_xlfn._xlws.SORT(B19:D19,1,1,TRUE))} -> -1 | F19: 0 | G19: 1 | H19: =IF(B19=E19,1,IF(B19=F19,2,3)) -> 2 | I19: number | J19: =LEFT(A19,LEN(A19)-4) -> 12-obf-v1 | AB19: =AB17/AB18 -> 103.56164
A20: 12-obf-v2.png | B20: 4 | C20: 3 | D20: 2 | E20: {=IF(D20="",_xlfn._xlws.SORT(B20:C20,1,1,TRUE),_xlfn._xlws.SORT(B20:D20,1,1,TRUE))} -> 2 | F20: 3 | G20: 4 | H20: =IF(B20=E20,1,IF(B20=F20,2,3)) -> 3 | I20: number | J20: =LEFT(A20,LEN(A20)-4) -> 12-obf-v2
A21: 13-clean-v0.png | B21: 5 | C21: 6 | D21: 3 | E21: {=IF(D21="",_xlfn._xlws.SORT(B21:C21,1,1,TRUE),_xlfn._xlws.SORT(B21:D21,1,1,TRUE))} -> 3 | F21: 5 | G21: 6 | H21: =IF(B21=E21,1,IF(B21=F21,2,3)) -> 2 | I21: number | J21: =LEFT(A21,LEN(A21)-4) -> 13-clean-v0
A22: 13-clean-v1.png | B22: 11 | C22: 4 | D22: 7 | E22: {=IF(D22="",_xlfn._xlws.SORT(B22:C22,1,1,TRUE),_xlfn._xlws.SORT(B22:D22,1,1,TRUE))} -> 4 | F22: 7 | G22: 11 | H22: =IF(B22=E22,1,IF(B22=F22,2,3)) -> 3 | I22: number | J22: =LEFT(A22,LEN(A22)-4) -> 13-clean-v1
A23: 13-clean-v2.png | B23: 5 | C23: 6 | D23: 8 | E23: {=IF(D23="",_xlfn._xlws.SORT(B23:C23,1,1,TRUE),_xlfn._xlws.SORT(B23:D23,1,1,TRUE))} -> 5 | F23: 6 | G23: 8 | H23: =IF(B23=E23,1,IF(B23=F23,2,3)) -> 1 | I23: number | J23: =LEFT(A23,LEN(A23)-4) -> 13-clean-v2 | AB23: =AB14/AB19 -> 49.439153
A24: 13-obf-v0.png | B24: 5 | C24: 6 | D24: 3 | E24: {=IF(D24="",_xlfn._xlws.SORT(B24:C24,1,1,TRUE),_xlfn._xlws.SORT(B24:D24,1,1,TRUE))} -> 3 | F24: 5 | G24: 6 | H24: =IF(B24=E24,1,IF(B24=F24,2,3)) -> 2 | I24: number | J24: =LEFT(A24,LEN(A24)-4) -> 13-obf-v0 | AB24: =AB23-AB18 -> 3.8141534
A25: 13-obf-v1.png | B25: 11 | C25: 4 | D25: 7 | E25: {=IF(D25="",_xlfn._xlws.SORT(B25:C25,1,1,TRUE),_xlfn._xlws.SORT(B25:D25,1,1,TRUE))} -> 4 | F25: 7 | G25: 11 | H25: =IF(B25=E25,1,IF(B25=F25,2,3)) -> 3 | I25: number | J25: =LEFT(A25,LEN(A25)-4) -> 13-obf-v1
A26: 13-obf-v2.png | B26: 5 | C26: 6 | D26: 8 | E26: {=IF(D26="",_xlfn._xlws.SORT(B26:C26,1,1,TRUE),_xlfn._xlws.SORT(B26:D26,1,1,TRUE))} -> 5 | F26: 6 | G26: 8 | H26: =IF(B26=E26,1,IF(B26=F26,2,3)) -> 1 | I26: number | J26: =LEFT(A26,LEN(A26)-4) -> 13-obf-v2
A27: 14-clean-v0.png | B27: 4 | C27: 1 | D27: 2 | E27: {=IF(D27="",_xlfn._xlws.SORT(B27:C27,1,1,TRUE),_xlfn._xlws.SORT(B27:D27,1,1,TRUE))} -> 1 | F27: 2 | G27: 4 | H27: =IF(B27=E27,1,IF(B27=F27,2,3)) -> 3 | I27: number | J27: =LEFT(A27,LEN(A27)-4) -> 14-clean-v0
A28: 14-clean-v1.png | B28: 12 | C28: 3 | D28: 4 | E28: {=IF(D28="",_xlfn._xlws.SORT(B28:C28,1,1,TRUE),_xlfn._xlws.SORT(B28:D28,1,1,TRUE))} -> 3 | F28: 4 | G28: 12 | H28: =IF(B28=E28,1,IF(B28=F28,2,3)) -> 3 | I28: number | J28: =LEFT(A28,LEN(A28)-4) -> 14-clean-v1
A29: 14-clean-v2.png | B29: 27 | C29: 30 | D29: 9 | E29: {=IF(D29="",_xlfn._xlws.SORT(B29:C29,1,1,TRUE),_xlfn._xlws.SORT(B29:D29,1,1,TRUE))} -> 9 | F29: 27 | G29: 30 | H29: =IF(B29=E29,1,IF(B29=F29,2,3)) -> 2 | I29: number | J29: =LEFT(A29,LEN(A29)-4) -> 14-clean-v2
A30: 14-obf-v0.png | B30: 4 | C30: 1 | D30: 2 | E30: {=IF(D30="",_xlfn._xlws.SORT(B30:C30,1,1,TRUE),_xlfn._xlws.SORT(B30:D30,1,1,TRUE))} -> 1 | F30: 2 | G30: 4 | H30: =IF(B30=E30,1,IF(B30=F30,2,3)) -> 3 | I30: number | J30: =LEFT(A30,LEN(A30)-4) -> 14-obf-v0
A31: 14-obf-v1.png | B31: 12 | C31: 3 | D31: 4 | E31: {=IF(D31="",_xlfn._xlws.SORT(B31:C31,1,1,TRUE),_xlfn._xlws.SORT(B31:D31,1,1,TRUE))} -> 3 | F31: 4 | G31: 12 | H31: =IF(B31=E31,1,IF(B31=F31,2,3)) -> 3 | I31: number | J31: =LEFT(A31,LEN(A31)-4) -> 14-obf-v1
A32: 14-obf-v2.png | B32: 27 | C32: 30 | D32: 9 | E32: {=IF(D32="",_xlfn._xlws.SORT(B32:C32,1,1,TRUE),_xlfn._xlws.SORT(B32:D32,1,1,TRUE))} -> 9 | F32: 27 | G32: 30 | H32: =IF(B32=E32,1,IF(B32=F32,2,3)) -> 2 | I32: number | J32: =LEFT(A32,LEN(A32)-4) -> 14-obf-v2
A33: 15-clean-v0.png | B33: 9.0 | C33: 8.0 | D33: 4.5 | E33: 4.5 | F33: 8.0 | G33: 9.0 | H33: =IF(B33=E33,1,IF(B33=F33,2,3)) -> 3 | I33: number | J33: =LEFT(A33,LEN(A33)-4) -> 15-clean-v0
A34: 15-clean-v1.png | B34: 13.0 | C34: 12.0 | D34: 14.0 | E34: 12.0 | F34: 13.0 | G34: 14.0 | H34: =IF(B34=E34,1,IF(B34=F34,2,3)) -> 2 | I34: number | J34: =LEFT(A34,LEN(A34)-4) -> 15-clean-v1
A35: 15-clean-v2.png | B35: 62.0 | C35: 312.0 | D35: 63.0 | E35: 62.0 | F35: 63.0 | G35: 312.0 | H35: =IF(B35=E35,1,IF(B35=F35,2,3)) -> 1 | I35: number | J35: =LEFT(A35,LEN(A35)-4) -> 15-clean-v2
A36: 15-obf-v0.png | B36: 9.0 | C36: 8.0 | D36: 4.5 | E36: 4.5 | F36: 8.0 | G36: 9.0 | H36: =IF(B36=E36,1,IF(B36=F36,2,3)) -> 3 | I36: number | J36: =LEFT(A36,LEN(A36)-4) -> 15-obf-v0
A37: 15-obf-v1.png | B37: 13.0 | C37: 12.0 | D37: 14.0 | E37: 12.0 | F37: 13.0 | G37: 14.0 | H37: =IF(B37=E37,1,IF(B37=F37,2,3)) -> 2 | I37: number | J37: =LEFT(A37,LEN(A37)-4) -> 15-obf-v1
A38: 15-obf-v2.png | B38: 62.0 | C38: 312.0 | D38: 63.0 | E38: 62.0 | F38: 63.0 | G38: 312.0 | H38: =IF(B38=E38,1,IF(B38=F38,2,3)) -> 1 | I38: number | J38: =LEFT(A38,LEN(A38)-4) -> 15-obf-v2
A39: 16-clean-v0.png | B39: 7 | C39: 5 | D39: 3 | E39: {=IF(D39="",_xlfn._xlws.SORT(B39:C39,1,1,TRUE),_xlfn._xlws.SORT(B39:D39,1,1,TRUE))} -> 3 | F39: 5 | G39: 7 | H39: =IF(B39=E39,1,IF(B39=F39,2,3)) -> 3 | I39: number | J39: =LEFT(A39,LEN(A39)-4) -> 16-clean-v0
A40: 16-clean-v1.png | B40: 5 | C40: 4 | D40: 6 | E40: {=IF(D40="",_xlfn._xlws.SORT(B40:C40,1,1,TRUE),_xlfn._xlws.SORT(B40:D40,1,1,TRUE))} -> 4 | F40: 5 | G40: 6 | H40: =IF(B40=E40,1,IF(B40=F40,2,3)) -> 2 | I40: number | J40: =LEFT(A40,LEN(A40)-4) -> 16-clean-v1
...
